Workbook

Sheet Summary
A1: FINANCIAL PLAN SUMMARY - SINGLE PAGE DASHBOARD
A3: Everything on this page is a live link. Change anything on the Inputs sheet and this dashboard, and every other sheet, updates instantly. Built to be reused for any client.
A5: CLIENT & CASH FLOW
A6: Item | B6: Value | C6: Unit | D6: Where It Comes From
A7: Client | B7: =Inputs!B7 -> Client A | D7: Inputs sheet.
A8: Age / Retirement Age / Life Expectancy | B8: =Inputs!B9&" / "&Inputs!B10&" / "&Inputs!B11 -> 24 / 60 / 85 | C8: years | D8: Inputs sheet.
A9: Annual Gross Income | B9: =Inputs!B18 -> 3500000 | C9: ₹ p.a. | D9: Inputs sheet.
A10: Annual Post-Tax Income | B10: =Inputs!B20 -> 2625000 | C10: ₹ p.a. | D10: Gross x (1 - effective tax rate).
A11: Annual Living Expenses | B11: =Inputs!B23 -> 900000 | C11: ₹ p.a. | D11: Monthly expenses x 12.
A12: Annual Insurance Premiums | B12: =Insurance!B78 -> 182300 | C12: ₹ p.a. | D12: Insurance sheet, section H.
A13: Monthly Investible Surplus | B13: =Inputs!B26 -> 128558.33 | C13: ₹ p.m. | D13: Post-tax income less expenses less premiums, divided by 12.
A14: Savings Rate | B14: =Inputs!B27 -> 0.58769524 | C14: % | D14: Investible surplus / post-tax income.
A15: Net Worth Today | B15: =Inputs!B39 -> 1000000 | C15: ₹ | D15: Assets less liabilities.
A17: STEP 1 - PROTECTION (buy this before investing a single rupee)
A18: Item | B18: Value | C18: Unit | D18: Where It Comes From
A19: Term Life Cover to Buy | B19: =Insurance!B48 -> 70000000 | C19: ₹ | D19: Highest of income-multiple, human life value and needs-based methods, less existing cover.
A20: Term Policy Tenure | B20: =Insurance!B49 -> 46 | C20: years | D20: To age 70.
A21: Estimated Term Premium | B21: =Insurance!B51 -> 73500 | C21: ₹ p.a. | D21: Cover / 1 lakh x age-banded rate.
A22: Health Base Cover to Hold | B22: =Insurance!B60 -> 3000000 | C22: ₹ | D22: MAX(age benchmark, 50% of income) x city factor x family loading.
A23: Super Top-Up to Add | B23: =Insurance!B61 -> 9000000 | C23: ₹ | D23: 3x the base cover, deductible equal to the base.
A24: Total Effective Health Cover | B24: =Insurance!B62 -> 12000000 | C24: ₹ | D24: Base + super top-up.
A25: Critical Illness Cover | B25: =Insurance!B71 -> 5000000 | C25: ₹ | D25: MIN(3x gross income, ₹50L).
A26: Personal Accident Cover | B26: =Insurance!B72 -> 20000000 | C26: ₹ | D26: 10x gross income.
A27: TOTAL ANNUAL PREMIUM | B27: =Insurance!B78 -> 182300 | C27: ₹ p.a. | D27: All five policies combined.
A28: Premium as % of Gross Income | B28: =Insurance!B80 -> 0.052085714 | C28: % | D28: Should stay under 5%.
A30: STEP 2 - EMERGENCY FUND & SHORT-TERM GOALS
A31: Item | B31: Value | C31: Unit | D31: Where It Comes From
A32: Emergency Fund Target | B32: =Inputs!B22*Inputs!B64 -> 450000 | C32: ₹ | D32: Monthly expenses x number of months set on the Inputs sheet.
A33: Total Future Cost of All Goals | B33: =Goals!$J$17 -> 71736593 | C33: ₹ | D33: Goals sheet, shortfall column total.
A34: Monthly SIP if All Goals Ran Concurrently | B34: =Goals!$K$17 -> 149116.28 | C34: ₹ p.m. | D34: Goals sheet, monthly SIP column total. The ceiling, not the plan - goals are sequenced.
A36: STEP 3 - RETIREMENT
A37: Item | B37: Value | C37: Unit | D37: Where It Comes From
A38: Years to Retirement | B38: =Inputs!B60 -> 36 | C38: years | D38: Retirement age less current age.
A39: First-Year Retirement Expense (nominal) | B39: =Retirement!B23 -> 5499395.1 | C39: ₹ p.a. | D39: Today's retirement expense inflated to the retirement date.
A40: RETIREMENT CORPUS REQUIRED | B40: =Retirement!B33 -> 1.476611e+08 | C40: ₹ | D40: Present value of inflation-linked withdrawals plus medical buffer and legacy.
A41: Same Corpus in Today's Money | B41: =Retirement!B34 -> 18124037 | C41: ₹ | D41: Corpus deflated back at general inflation.
A42: Value of Existing Corpus at Retirement | B42: =Retirement!B41 -> 31583805 | C42: ₹ | D42: Existing investments compounded at the blended return.
A43: CORPUS GAP TO FUND | B43: =Retirement!B44 -> 1.160773e+08 | C43: ₹ | D43: Required less expected. This is what new investing must create.
A44: Level Monthly SIP (never increased) | B44: =Retirement!B48 -> 22545.181 | C44: ₹ p.m. | D44: Retirement sheet, option 1.
A45: RECOMMENDED: Step-Up SIP, year 1 | B45: =Retirement!B49 -> 8468.2705 | C45: ₹ p.m. | D45: Retirement sheet, option 2. Raise it 10% every year as income grows.
...

Sheet Inputs
A1: 1. CLIENT INPUTS & PLANNING ASSUMPTIONS
A3: HOW TO USE: edit only the YELLOW cells (blue text). Every other cell on every sheet is a live formula that recalculates automatically. Black = formula on this sheet, green = pulled from another sheet.
A5: A. CLIENT PROFILE
A6: Parameter | B6: Value | C6: Unit | D6: Formula / Logic Used
A7: Client Name | B7: Client A | C7: text | D7: Free text label used on the Summary sheet.
A8: Plan Start Date (financial year) | B8: FY 2026-27 | C8: text | D8: Reference year for all 'today's cost' figures.
A9: Current Age | B9: 24 | C9: years | D9: Drives insurance multiples, premium rates and the allocation glide path.
A10: Planned Retirement Age | B10: 60 | C10: years | D10: End of the accumulation phase.
A11: Life Expectancy | B11: 85 | C11: years | D11: Corpus must last until this age. Conservative for a 24-year-old today.
A12: Number of Financial Dependents | B12: 2 | C12: count | D12: Used in the needs-based life cover method.
A13: Family Members to Insure (Health) | B13: 3 | C13: count | D13: Self + spouse + children on a floater policy.
A14: City Tier Factor | B14: 1 | C14: x | D14: Metro = 1.00, Tier-2 = 0.80, Tier-3 = 0.65. Scales the health cover benchmark to local hospitalisation costs.
A16: B. INCOME & CASH FLOW
A17: Parameter | B17: Value | C17: Unit | D17: Formula / Logic Used
A18: Annual Gross Income | B18: 3500000 | C18: ₹ p.a. | D18: Mid-point of the ₹30-40 lakh range. Change to run the plan at either end.
A19: Effective Tax Rate | B19: 0.25 | C19: % | D19: All-in effective rate (new regime, ₹35L salary, incl. cess). Not the marginal slab.
A20: Annual Post-Tax Income | B20: =B18*(1-B19) -> 2625000 | C20: ₹ p.a. | D20: Formula: Gross Income x (1 - Effective Tax Rate)
A21: Monthly Post-Tax Income | B21: =B20/12 -> 218750 | C21: ₹ p.m. | D21: Formula: Annual Post-Tax Income / 12
A22: Monthly Household Expenses | B22: 75000 | C22: ₹ p.m. | D22: All living costs incl. rent, EMIs (interest), lifestyle. Excludes investments.
A23: Annual Household Expenses | B23: =B22*12 -> 900000 | C23: ₹ p.a. | D23: Formula: Monthly Expenses x 12
A24: Annual Insurance Premium Outgo | B24: =Insurance!B78 -> 182300 | C24: ₹ p.a. | D24: Total of term + health + super top-up + critical illness + accident premiums. Pulled from the Insurance sheet.
A25: Annual Investible Surplus | B25: =B20-B23-B24 -> 1542700 | C25: ₹ p.a. | D25: Formula: Post-Tax Income - Living Expenses - Insurance Premiums
A26: Monthly Investible Surplus | B26: =B25/12 -> 128558.33 | C26: ₹ p.m. | D26: Formula: Annual Investible Surplus / 12. This is the budget every SIP on this workbook must fit inside.
A27: Savings Rate | B27: =IF(B20=0,0,B25/B20) -> 0.58769524 | C27: % | D27: Formula: Investible Surplus / Post-Tax Income. Target 40%+ at this age and income.
A28: Expected Annual Income Growth | B28: 0.08 | C28: % | D28: Supports the step-up SIP assumption - if income grows 8%, a 10% SIP step-up is affordable.
A30: C. EXISTING ASSETS & LIABILITIES
A31: Parameter | B31: Value | C31: Unit | D31: Formula / Logic Used
A32: Existing Equity Investments (MF / stocks / NPS-E) | B32: 500000 | C32: ₹ | D32: Market value today.
A33: Existing Debt Investments (EPF / PPF / debt MF) | B33: 300000 | C33: ₹ | D33: Balance today.
A34: Existing Cash, FD & Liquid Funds | B34: 200000 | C34: ₹ | D34: Includes anything already set aside as emergency money.
A35: Total Existing Corpus | B35: =SUM(B32:B34) -> 1000000 | C35: ₹ | D35: Formula: Equity + Debt + Cash
A36: Outstanding Home Loan | B36: 0 | C36: ₹ | D36: Principal outstanding.
A37: Other Loans (car / personal / education) | B37: 0 | C37: ₹ | D37: Principal outstanding.
A38: Total Liabilities | B38: =SUM(B36:B37) -> 0 | C38: ₹ | D38: Formula: Home Loan + Other Loans. Must be fully covered by life insurance.
A39: Net Worth | B39: =B35-B38 -> 1000000 | C39: ₹ | D39: Formula: Total Assets - Total Liabilities
A40: Existing Life Cover (term + employer + others) | B40: 0 | C40: ₹ | D40: Employer group cover is not portable - count it, but do not rely on it.
A41: Existing Health Cover (personal + employer) | B41: 500000 | C41: ₹ | D41: Typically employer floater only, at this stage.
A43: D. INFLATION & RETURN ASSUMPTIONS
A44: Parameter | B44: Value | C44: Unit | D44: Formula / Logic Used
A45: General Inflation (CPI) | B45: 0.06 | C45: % | D45: Long-run Indian CPI assumption. Applied to living expenses and generic goals.
...

Sheet Insurance
A1: 2. INSURANCE PLANNING - LIFE, HEALTH, CRITICAL ILLNESS, ACCIDENT
A3: PRIORITY ORDER: risk cover is bought BEFORE any investment. An uninsured medical event or death destroys a portfolio far faster than any market fall. Buy term + health first, then invest the balance.
A5: A. CLIENT SNAPSHOT (pulled from the Inputs sheet)
A6: Parameter | B6: Value | C6: Unit | D6: Formula / Logic Used
A7: Current Age | B7: =Inputs!B9 -> 24 | C7: years | D7: Link to Inputs.
A8: Annual Gross Income | B8: =Inputs!B18 -> 3500000 | C8: ₹ p.a. | D8: Link to Inputs.
A9: Annual Post-Tax Income | B9: =Inputs!B20 -> 2625000 | C9: ₹ p.a. | D9: Link to Inputs.
A10: Years to Retirement | B10: =Inputs!B60 -> 36 | C10: years | D10: Income-earning years remaining.
A11: Total Liabilities | B11: =Inputs!B38 -> 0 | C11: ₹ | D11: Must be extinguished by the death benefit.
A12: Total Existing Corpus | B12: =Inputs!B35 -> 1000000 | C12: ₹ | D12: Assets the family already has - reduces cover needed.
A13: Existing Life Cover | B13: =Inputs!B40 -> 0 | C13: ₹ | D13: Deducted from the requirement.
A14: Existing Health Cover | B14: =Inputs!B41 -> 500000 | C14: ₹ | D14: Deducted from the requirement.
A15: Safe Real Discount Rate | B15: =Inputs!B56 -> 0.0094339623 | C15: % | D15: Debt-return-based real rate. Used for all present-value insurance maths.
A17: B. LIFE INSURANCE - METHOD 1: INCOME MULTIPLE (THUMB RULE)
A18: Parameter | B18: Value | C18: Unit | D18: Formula / Logic Used
A19: Applicable Income Multiple | B19: =INDEX(Tables!$B$5:$B$10,MATCH(B7,Tables!$A$5:$A$10,1)) -> 20 | C19: x | D19: Formula: INDEX(multiples, MATCH(Age, age-bands, 1)). Approximate-match lookup on the Tables sheet: the multiple falls as the client ages because fewer earning years remain.
A20: Cover by Income Multiple | B20: =B8*B19 -> 70000000 | C20: ₹ | D20: Formula: Annual Gross Income x Multiple. Fast sanity check only - it ignores liabilities, assets and actual family need.
A22: C. LIFE INSURANCE - METHOD 2: HUMAN LIFE VALUE (INCOME REPLACEMENT)
A23: Parameter | B23: Value | C23: Unit | D23: Formula / Logic Used
A24: Self-Consumption Share of Income | B24: 0.3 | C24: % | D24: The portion the earner spends on themselves, which the family no longer needs. 25-35% is standard.
A25: Income Available to Family (annual) | B25: =B9*(1-B24) -> 1837500 | C25: ₹ p.a. | D25: Formula: Post-Tax Income x (1 - Self-Consumption Share)
A26: Present Value of Lost Future Income | B26: =PV(B15,B10,-B25) -> 55866646 | C26: ₹ | D26: Formula: PV(real safe rate, years to retirement, -annual income to family). Using the REAL rate means the payout can be raised with inflation every year, so the family's standard of living is preserved.
A27: Add: Outstanding Liabilities | B27: =B11 -> 0 | C27: ₹ | D27: Loans must be cleared, not serviced, on death.
A28: Less: Existing Corpus | B28: =-B12 -> -1000000 | C28: ₹ | D28: Assets already available to the family.
A29: Human Life Value Cover Required | B29: =MAX(0,SUM(B26:B28)) -> 54866646 | C29: ₹ | D29: Formula: PV of income + Liabilities - Existing Corpus
A31: D. LIFE INSURANCE - METHOD 3: NEEDS-BASED (MOST ACCURATE)
A32: Parameter | B32: Value | C32: Unit | D32: Formula / Logic Used
A33: Family Expenses if Earner Dies (annual) | B33: =Inputs!B23*0.75 -> 675000 | C33: ₹ p.a. | D33: Formula: Current Annual Household Expenses x 75%. Household costs fall, but not proportionally - one fewer person does not mean 33% less spending.
A34: Dependency Period | B34: =Inputs!B11-Inputs!B9 -> 61 | C34: years | D34: Formula: Life Expectancy - Current Age. The family needs income support for the SPOUSE'S whole remaining life, not just until the earner would have retired.
A35: Present Value of Family Expenses | B35: =PV(B15,B34,-B33) -> 31198751 | C35: ₹ | D35: Formula: PV(real safe rate, dependency years, -annual family expenses)
A36: Add: Outstanding Liabilities | B36: =B11 -> 0 | C36: ₹ | D36: Home loan / other loans repaid in full.
A37: Add: Children's Education Corpus (today's value) | B37: 3000000 | C37: ₹ | D37: Present-day cost of the education goals the earner promised to fund.
A38: Add: Children's Marriage Corpus (today's value) | B38: 2500000 | C38: ₹ | D38: Present-day cost. Set to 0 if not a planned goal.
A39: Add: Funeral / Immediate Estate Costs | B39: 500000 | C39: ₹ | D39: Immediate liquidity for the family in the first 6 months.
A40: Less: Existing Corpus | B40: =-B12 -> -1000000 | C40: ₹ | D40: Assets the family can draw on.
A41: Needs-Based Cover Required | B41: =MAX(0,SUM(B35:B40)) -> 36198751 | C41: ₹ | D41: Formula: PV of expenses + Liabilities + Education + Marriage + Estate costs - Existing Corpus
A43: E. LIFE INSURANCE - RECOMMENDATION
A44: Parameter | B44: Value | C44: Unit | D44: Formula / Logic Used
A45: Highest of the Three Methods | B45: =MAX(B20,B29,B41) -> 70000000 | C45: ₹ | D45: Formula: MAX(Income Multiple, HLV, Needs-Based). Always plan to the highest - under-insurance cannot be fixed after the event.
A46: Less: Existing Life Cover | B46: =-B13 -> 0 | C46: ₹ | D46: Employer group cover counts here but disappears when the job does.
...

Sheet Goals
A1: 3. GOAL PLANNING - EMERGENCY FUND, SHORT TERM & LONG TERM
A2: Edit the YELLOW cells only (goal name, horizon, today's cost, inflation rate, money already earmarked, expected return). Every other column is a live formula. Add rows inside the table and copy the formulas down.
A4: Goal | B4: Priority | C4: Years to Goal | D4: Cost Today (₹) | E4: Inflation Rate | F4: Future Cost at Goal Date (₹) | G4: Already Earmarked (₹) | H4: Expected Return | I4: FV of Earmarked (₹) | J4: Shortfall to Fund (₹) | K4: Monthly SIP Needed (₹) | L4: One-Time Lumpsum Today (₹)
A5: Emergency Fund (6 months expenses) | B5: Critical | C5: 1 | D5: =Inputs!B22*Inputs!B64 -> 450000 | E5: =Inputs!$B$45 -> 0.06 | F5: =IF($C5="","",FV($E5,$C5,0,-$D5)) -> 477000 | G5: =Inputs!B34 -> 200000 | H5: 0.065 | I5: =IF($C5="","",FV($H5,$C5,0,-$G5)) -> 213000 | J5: =IF($C5="","",MAX(0,$F5-$I5)) -> 264000 | K5: =IF($C5="","",IF($J5=0,0,-PMT($H5/12,$C5*12,0,$J5))) -> 21352.254 | L5: =IF($C5="","",$J5/(1+$H5)^$C5) -> 247887.32
A6: International Holiday | B6: Low | C6: 2 | D6: 300000 | E6: =Inputs!$B$45 -> 0.06 | F6: =IF($C6="","",FV($E6,$C6,0,-$D6)) -> 337080 | G6: 0 | H6: 0.08 | I6: =IF($C6="","",FV($H6,$C6,0,-$G6)) -> 0 | J6: =IF($C6="","",MAX(0,$F6-$I6)) -> 337080 | K6: =IF($C6="","",IF($J6=0,0,-PMT($H6/12,$C6*12,0,$J6))) -> 12998.015 | L6: =IF($C6="","",$J6/(1+$H6)^$C6) -> 288991.77
A7: Upskilling / Certification / PG | B7: High | C7: 5 | D7: 1000000 | E7: =Inputs!$B$47 -> 0.08 | F7: =IF($C7="","",FV($E7,$C7,0,-$D7)) -> 1469328.1 | G7: 0 | H7: 0.1 | I7: =IF($C7="","",FV($H7,$C7,0,-$G7)) -> 0 | J7: =IF($C7="","",MAX(0,$F7-$I7)) -> 1469328.1 | K7: =IF($C7="","",IF($J7=0,0,-PMT($H7/12,$C7*12,0,$J7))) -> 18974.479 | L7: =IF($C7="","",$J7/(1+$H7)^$C7) -> 912337.13
A8: Wedding | B8: High | C8: 5 | D8: 1500000 | E8: =Inputs!$B$45 -> 0.06 | F8: =IF($C8="","",FV($E8,$C8,0,-$D8)) -> 2007338.4 | G8: 0 | H8: 0.1 | I8: =IF($C8="","",FV($H8,$C8,0,-$G8)) -> 0 | J8: =IF($C8="","",MAX(0,$F8-$I8)) -> 2007338.4 | K8: =IF($C8="","",IF($J8=0,0,-PMT($H8/12,$C8*12,0,$J8))) -> 25922.188 | L8: =IF($C8="","",$J8/(1+$H8)^$C8) -> 1246399.2
A9: Car Purchase (down payment + on-road) | B9: Medium | C9: 7 | D9: 1000000 | E9: =Inputs!$B$45 -> 0.06 | F9: =IF($C9="","",FV($E9,$C9,0,-$D9)) -> 1503630.3 | G9: 0 | H9: 0.11 | I9: =IF($C9="","",FV($H9,$C9,0,-$G9)) -> 0 | J9: =IF($C9="","",MAX(0,$F9-$I9)) -> 1503630.3 | K9: =IF($C9="","",IF($J9=0,0,-PMT($H9/12,$C9*12,0,$J9))) -> 11962.536 | L9: =IF($C9="","",$J9/(1+$H9)^$C9) -> 724236.16
A10: Home Down Payment (20% of ₹1.5 Cr) | B10: High | C10: 10 | D10: 3000000 | E10: 0.07 | F10: =IF($C10="","",FV($E10,$C10,0,-$D10)) -> 5901454.1 | G10: 0 | H10: 0.11 | I10: =IF($C10="","",FV($H10,$C10,0,-$G10)) -> 0 | J10: =IF($C10="","",MAX(0,$F10-$I10)) -> 5901454.1 | K10: =IF($C10="","",IF($J10=0,0,-PMT($H10/12,$C10*12,0,$J10))) -> 27195.874 | L10: =IF($C10="","",$J10/(1+$H10)^$C10) -> 2078400.5
A11: Child - Higher Education (undergrad) | B11: High | C11: 22 | D11: 3000000 | E11: =Inputs!$B$47 -> 0.08 | F11: =IF($C11="","",FV($E11,$C11,0,-$D11)) -> 16309621 | G11: 0 | H11: 0.12 | I11: =IF($C11="","",FV($H11,$C11,0,-$G11)) -> 0 | J11: =IF($C11="","",MAX(0,$F11-$I11)) -> 16309621 | K11: =IF($C11="","",IF($J11=0,0,-PMT($H11/12,$C11*12,0,$J11))) -> 12711.451 | L11: =IF($C11="","",$J11/(1+$H11)^$C11) -> 1347868
A12: Child - Post Graduation / Abroad | B12: Medium | C12: 26 | D12: 4000000 | E12: =Inputs!$B$47 -> 0.08 | F12: =IF($C12="","",FV($E12,$C12,0,-$D12)) -> 29585413 | G12: 0 | H12: 0.12 | I12: =IF($C12="","",FV($H12,$C12,0,-$G12)) -> 0 | J12: =IF($C12="","",MAX(0,$F12-$I12)) -> 29585413 | K12: =IF($C12="","",IF($J12=0,0,-PMT($H12/12,$C12*12,0,$J12))) -> 13891.079 | L12: =IF($C12="","",$J12/(1+$H12)^$C12) -> 1553849.8
A13: Child - Marriage | B13: Medium | C13: 30 | D13: 2500000 | E13: =Inputs!$B$45 -> 0.06 | F13: =IF($C13="","",FV($E13,$C13,0,-$D13)) -> 14358728 | G13: 0 | H13: 0.12 | I13: =IF($C13="","",FV($H13,$C13,0,-$G13)) -> 0 | J13: =IF($C13="","",MAX(0,$F13-$I13)) -> 14358728 | K13: =IF($C13="","",IF($J13=0,0,-PMT($H13/12,$C13*12,0,$J13))) -> 4108.4049 | L13: =IF($C13="","",$J13/(1+$H13)^$C13) -> 479264.53
F14: =IF($C14="","",FV($E14,$C14,0,-$D14)) | I14: =IF($C14="","",FV($H14,$C14,0,-$G14)) | J14: =IF($C14="","",MAX(0,$F14-$I14)) | K14: =IF($C14="","",IF($J14=0,0,-PMT($H14/12,$C14*12,0,$J14))) | L14: =IF($C14="","",$J14/(1+$H14)^$C14)
F15: =IF($C15="","",FV($E15,$C15,0,-$D15)) | I15: =IF($C15="","",FV($H15,$C15,0,-$G15)) | J15: =IF($C15="","",MAX(0,$F15-$I15)) | K15: =IF($C15="","",IF($J15=0,0,-PMT($H15/12,$C15*12,0,$J15))) | L15: =IF($C15="","",$J15/(1+$H15)^$C15)
F16: =IF($C16="","",FV($E16,$C16,0,-$D16)) | I16: =IF($C16="","",FV($H16,$C16,0,-$G16)) | J16: =IF($C16="","",MAX(0,$F16-$I16)) | K16: =IF($C16="","",IF($J16=0,0,-PMT($H16/12,$C16*12,0,$J16))) | L16: =IF($C16="","",$J16/(1+$H16)^$C16)
A17: TOTAL | D17: =SUM(D5:D16) -> 16750000 | F17: =SUM(F5:F16) -> 71949593 | G17: =SUM(G5:G16) -> 200000 | I17: =SUM(I5:I16) -> 213000 | J17: =SUM(J5:J16) -> 71736593 | K17: =SUM(K5:K16) -> 149116.28 | L17: =SUM(L5:L16) -> 8879234.5
A19: AFFORDABILITY CHECK - WHAT IS ACTUALLY FUNDABLE TODAY
A20: Monthly Investible Surplus available | B20: =Inputs!B26 -> 128558.33 | D20: From the Inputs sheet: post-tax income less living expenses less insurance premiums.
A21: Monthly SIP if ALL goals ran concurrently | B21: =K17 -> 149116.28 | D21: Formula: SUM of the Monthly SIP Needed column. Goals rarely all start on day one, so treat this as the ceiling, not the plan.
A22: Monthly SIP for CRITICAL + HIGH priority goals | B22: =SUMIF($B$5:$B$16,"Critical",$K$5:$K$16)+SUMIF($B$5:$B$16,"High",$K$5:$K$16) -> 106156.25 | D22: Formula: SUMIF(priority range, "Critical", SIP range) + SUMIF(priority range, "High", SIP range). Adds only the SIPs whose priority cell reads Critical or High. This is what starts now.
A23: Monthly SIP for MEDIUM + LOW priority goals (deferrable) | B23: =B21-B22 -> 42960.035 | D23: Formula: All-goals SIP - Critical & High SIP. Start these as income rises or as earlier goals complete and free up their instalment.
A24: Monthly SIP for Retirement (step-up, year 1) | B24: =Retirement!B49 -> 8468.2705 | D24: Pulled from the Retirement sheet. Non-negotiable - it has the longest runway and the least ability to be made up later.
A25: COMMITTED NOW (Critical + High goals + Retirement) | B25: =B22+B24 -> 114624.52 | D25: Formula: Critical & High goal SIPs + Retirement SIP. The monthly commitment the client actually takes on today.
A26: Surplus / (Deficit) after what is committed now | B26: =B20-B25 -> 13933.817 | D26: Formula: Investible Surplus - Committed Now. Positive means the plan is fundable as written. Negative means stretch a horizon, trim a goal amount, or raise income before adding anything.
A27: Committed as % of Investible Surplus | B27: =IFERROR(B25/B20,0) -> 0.89161483 | D27: Formula: Committed Now / Investible Surplus. Anything under 100% is fundable.
A28: Surplus / (Deficit) if every goal ran concurrently | B28: =B20-B21-B24 -> -29026.219 | D28: Formula: Surplus - All-goals SIP - Retirement SIP. Usually negative, and that is the point: it is the arithmetic proof that goals must be SEQUENCED, not stacked.
A30: SEQUENCING NOTE: the emergency fund is a one-year push - once it is full, its entire instalment is released to the next goal. Every completed goal does the same. That rolling release, plus the 8% expected income growth on the Inputs sheet, is how the medium and low priority goals get funded without ever exceeding the surplus.
A33: COLUMN FORMULAS EXPLAINED
A34: Future Cost at Goal Date | B34: Formula: FV(Inflation, Years, 0, -Cost Today) | E34: Compounds today's price forward at the goal's own inflation rate. Education inflates faster than groceries, so each goal carries its own rate.
A35: FV of Earmarked | B35: Formula: FV(Expected Return, Years, 0, -Already Earmarked) | E35: Money already set aside for this goal keeps growing. Only the shortfall needs new money.
A36: Shortfall to Fund | B36: Formula: MAX(0, Future Cost - FV of Earmarked) | E36: The real funding requirement, floored at zero so an over-funded goal does not net off against others.
A37: Monthly SIP Needed | B37: Formula: -PMT(Return/12, Years*12, 0, Shortfall) | E37: The level monthly instalment whose future value equals the shortfall. Negated because PMT returns a cash OUTFLOW as a negative number.
A38: One-Time Lumpsum Today | B38: Formula: Shortfall / (1 + Return)^Years | E38: The single amount invested today that grows into the shortfall. Present value of a single future sum.
A39: Expected Return set by horizon | B39: under 3 yrs 6.5-8% (liquid/arbitrage) | 3-7 yrs 9-11% (hybrid) | over 7 yrs 12% (equity) | E39: Never fund a goal under 3 years away with equity. The horizon dictates the asset class, and the asset class dictates the return you may assume.

Sheet Retirement
A1: 4. RETIREMENT PLANNING - CORPUS REQUIRED & HOW TO GET THERE
A3: The corpus is sized so that withdrawals RISE WITH INFLATION every single year of retirement and the money still lasts to life expectancy. That is what the real-rate annuity-due present value below does.
A5: A. RETIREMENT PARAMETERS
A6: Parameter | B6: Value | C6: Unit | D6: Formula / Logic Used
A7: Current Age | B7: =Inputs!B9 -> 24 | C7: years | D7: Link to Inputs.
A8: Retirement Age | B8: =Inputs!B10 -> 60 | C8: years | D8: Link to Inputs.
A9: Life Expectancy | B9: =Inputs!B11 -> 85 | C9: years | D9: Link to Inputs.
A10: Years to Retirement (accumulation) | B10: =Inputs!B60 -> 36 | C10: years | D10: Formula: Retirement Age - Current Age. 36 years of compounding is the single biggest asset this client has.
A11: Years in Retirement (drawdown) | B11: =Inputs!B62 -> 25 | C11: years | D11: Formula: Life Expectancy - Retirement Age
A12: General Inflation | B12: =Inputs!B45 -> 0.06 | C12: % | D12: Link to Inputs.
A13: Blended Pre-Retirement Return | B13: =Inputs!B51 -> 0.1075 | C13: % | D13: Link to Inputs.
A14: Post-Retirement Return | B14: =Inputs!B52 -> 0.075 | C14: % | D14: Link to Inputs.
A15: Real Post-Retirement Return | B15: =Inputs!B55 -> 0.014150943 | C15: % | D15: Formula: (1+Post-Ret Return)/(1+Inflation)-1. The rate at which the corpus outgrows inflation during drawdown.
A16: Annual SIP Step-Up Rate | B16: =Inputs!B53 -> 0.1 | C16: % | D16: Link to Inputs.
A18: B. RETIREMENT EXPENSE PROJECTION
A19: Parameter | B19: Value | C19: Unit | D19: Formula / Logic Used
A20: Current Annual Household Expenses | B20: =Inputs!B23 -> 900000 | C20: ₹ p.a. | D20: Link to Inputs.
A21: Retirement Expense Ratio | B21: =Inputs!B63 -> 0.75 | C21: % | D21: Link to Inputs. Commuting, work clothes, child costs and EMIs go; healthcare and leisure rise.
A22: Retirement Expenses in TODAY'S money | B22: =B20*B21 -> 675000 | C22: ₹ p.a. | D22: Formula: Current Annual Expenses x Retirement Expense Ratio
A23: Annual Expenses in the FIRST year of retirement | B23: =FV(B12,B10,0,-B22) -> 5499395.1 | C23: ₹ p.a. | D23: Formula: FV(Inflation, Years to Retirement, 0, -Today's Retirement Expense). This is the number that shocks clients: 36 years of 6% inflation multiplies today's cost roughly 8x.
A24: Monthly Expenses in the first year of retirement | B24: =B23/12 -> 458282.92 | C24: ₹ p.m. | D24: Formula: Annual first-year retirement expense / 12
A26: C. CORPUS REQUIRED AT RETIREMENT
A27: Parameter | B27: Value | C27: Unit | D27: Formula / Logic Used
A28: Corpus to Fund Inflation-Linked Living Expenses | B28: =PV(B15,B11,-B23,0,1) -> 1.1674842e+08 | C28: ₹ | D28: Formula: PV(Real Post-Ret Return, Years in Retirement, -First-Year Expense, 0, 1). Annuity-DUE (the trailing 1) because the year's expenses are withdrawn at the START of the year. Discounting at the REAL rate is what lets every future withdrawal rise with inflation.
A29: Medical Buffer (today's value) | B29: 1000000 | C29: ₹ | D29: A ring-fenced sum for treatment not covered by insurance. Grows at MEDICAL inflation, not CPI.
A30: Medical Buffer at Retirement | B30: =FV(Inputs!B46,B10,0,-B29) -> 30912681 | C30: ₹ | D30: Formula: FV(Medical Inflation, Years to Retirement, 0, -Medical Buffer Today)
A31: Legacy / Estate to Leave Behind (today's value) | B31: 0 | C31: ₹ | D31: Set above zero if the client wants to bequeath a specific amount.
A32: Legacy at Retirement | B32: =FV(B12,B10,0,-B31) -> 0 | C32: ₹ | D32: Formula: FV(Inflation, Years to Retirement, 0, -Legacy Today)
A33: TOTAL RETIREMENT CORPUS REQUIRED | B33: =B28+B30+B32 -> 1.476611e+08 | C33: ₹ | D33: Formula: Living Expense Corpus + Medical Buffer + Legacy
A34: Corpus in TODAY'S purchasing power | B34: =B33/(1+B12)^B10 -> 18124037 | C34: ₹ | D34: Formula: Corpus / (1 + Inflation) ^ Years to Retirement. Deflating the headline number back to today makes it comprehensible - the crore figure is large mostly because money shrinks.
A35: Cross-check: 30x First-Year Expense | B35: =B23*30 -> 1.6498185e+08 | C35: ₹ | D35: Formula: First-Year Retirement Expense x 30. The 3.33% safe-withdrawal thumb rule. Should land within ~15% of the PV answer; a big divergence means an assumption needs revisiting.
A36: Implied Initial Withdrawal Rate | B36: =IFERROR(B23/B33,0) -> 0.037243357 | C36: % | D36: Formula: First-Year Expense / Total Corpus. Anything at or under 4% is historically survivable over a 25-year retirement; under 3.5% for a 25-year-plus retirement.
A38: D. WHAT THE CLIENT ALREADY HAS
A39: Parameter | B39: Value | C39: Unit | D39: Formula / Logic Used
A40: Existing Corpus Available for Retirement | B40: =Inputs!B32+Inputs!B33 -> 800000 | C40: ₹ | D40: Formula: Existing Equity + Existing Debt. Deliberately EXCLUDES the cash and FD balance, because that money is earmarked as the emergency fund on the Goals sheet and counting it twice would overstate the retirement position.
A41: Future Value of Existing Corpus at Retirement | B41: =FV(B13,B10,0,-B40) -> 31583805 | C41: ₹ | D41: Formula: FV(Blended Return, Years to Retirement, 0, -Existing Corpus). Money already invested does the heavy lifting - it compounds for the full 36 years untouched.
A42: Expected EPF Accumulation at Retirement | B42: 0 | C42: ₹ | D42: Optional. Enter the projected EPF/NPS employer-side balance at 60 if it is not already inside the Existing Corpus figure, so it is not double-counted.
A43: Total Expected Without New Investment | B43: =B41+B42 -> 31583805 | C43: ₹ | D43: Formula: FV of Existing Corpus + EPF
A44: RETIREMENT CORPUS GAP | B44: =MAX(0,B33-B43) -> 1.160773e+08 | C44: ₹ | D44: Formula: Total Corpus Required - Total Expected. This is the amount that new monthly investing has to create.
A46: E. HOW TO FUND THE GAP
...

Sheet Projection
A1: 5. YEAR-BY-YEAR CORPUS PROJECTION (accumulation then drawdown)
A2: Fully formula-driven off the Inputs and Retirement sheets. Two built-in reconciliations: the closing corpus in the year before retirement should match the corpus requirement on the Retirement sheet almost exactly, and the balance surviving to life expectancy should be the medical buffer and legacy still compounding, because the living-expense portion is designed to be spent down to zero. If either check drifts, an assumption has been changed inconsistently.
A4: Year | B4: Age | C4: Phase | D4: Opening Corpus (₹) | E4: Annual Investment (₹) | F4: Annual Withdrawal (₹) | G4: Return Rate | H4: Growth (₹) | I4: Closing Corpus (₹) | J4: Closing in Today's Money (₹)
A5: 1 | B5: =IF(Inputs!$B$9+0>Inputs!$B$11,"",Inputs!$B$9+0) -> 24 | C5: =IF($B5>Inputs!$B$11,"",IF($B5<Inputs!$B$10,"Accumulation","Retirement")) -> Accumulation | D5: =IF($B5>Inputs!$B$11,"",Retirement!$B$40) -> 800000 | E5: =IF($B5>Inputs!$B$11,"",IF($B5>=Inputs!$B$10,0,Retirement!$B$49*12*(1+Inputs!$B$53)^(A5-1))) -> 101619.25 | F5: =IF($B5>Inputs!$B$11,"",IF($B5<Inputs!$B$10,0,Retirement!$B$23*(1+Inputs!$B$45)^($B5-Inputs!$B$10))) -> 0 | G5: =IF($B5>Inputs!$B$11,"",IF($B5<Inputs!$B$10,Inputs!$B$51,Inputs!$B$52)) -> 0.1075 | H5: =IF($B5>Inputs!$B$11,"",(D5-F5)*G5) -> 86000 | I5: =IF($B5>Inputs!$B$11,"",D5-F5+H5+E5) -> 987619.25 | J5: =IF($B5>Inputs!$B$11,"",I5/(1+Inputs!$B$45)^A5) -> 931716.27
A6: 2 | B6: =IF(Inputs!$B$9+1>Inputs!$B$11,"",Inputs!$B$9+1) -> 25 | C6: =IF($B6>Inputs!$B$11,"",IF($B6<Inputs!$B$10,"Accumulation","Retirement")) -> Accumulation | D6: =IF($B6>Inputs!$B$11,"",I5) -> 987619.25 | E6: =IF($B6>Inputs!$B$11,"",IF($B6>=Inputs!$B$10,0,Retirement!$B$49*12*(1+Inputs!$B$53)^(A6-1))) -> 111781.17 | F6: =IF($B6>Inputs!$B$11,"",IF($B6<Inputs!$B$10,0,Retirement!$B$23*(1+Inputs!$B$45)^($B6-Inputs!$B$10))) -> 0 | G6: =IF($B6>Inputs!$B$11,"",IF($B6<Inputs!$B$10,Inputs!$B$51,Inputs!$B$52)) -> 0.1075 | H6: =IF($B6>Inputs!$B$11,"",(D6-F6)*G6) -> 106169.07 | I6: =IF($B6>Inputs!$B$11,"",D6-F6+H6+E6) -> 1205569.5 | J6: =IF($B6>Inputs!$B$11,"",I6/(1+Inputs!$B$45)^A6) -> 1072952.5
A7: 3 | B7: =IF(Inputs!$B$9+2>Inputs!$B$11,"",Inputs!$B$9+2) -> 26 | C7: =IF($B7>Inputs!$B$11,"",IF($B7<Inputs!$B$10,"Accumulation","Retirement")) -> Accumulation | D7: =IF($B7>Inputs!$B$11,"",I6) -> 1205569.5 | E7: =IF($B7>Inputs!$B$11,"",IF($B7>=Inputs!$B$10,0,Retirement!$B$49*12*(1+Inputs!$B$53)^(A7-1))) -> 122959.29 | F7: =IF($B7>Inputs!$B$11,"",IF($B7<Inputs!$B$10,0,Retirement!$B$23*(1+Inputs!$B$45)^($B7-Inputs!$B$10))) -> 0 | G7: =IF($B7>Inputs!$B$11,"",IF($B7<Inputs!$B$10,Inputs!$B$51,Inputs!$B$52)) -> 0.1075 | H7: =IF($B7>Inputs!$B$11,"",(D7-F7)*G7) -> 129598.72 | I7: =IF($B7>Inputs!$B$11,"",D7-F7+H7+E7) -> 1458127.5 | J7: =IF($B7>Inputs!$B$11,"",I7/(1+Inputs!$B$45)^A7) -> 1224272
A8: 4 | B8: =IF(Inputs!$B$9+3>Inputs!$B$11,"",Inputs!$B$9+3) -> 27 | C8: =IF($B8>Inputs!$B$11,"",IF($B8<Inputs!$B$10,"Accumulation","Retirement")) -> Accumulation | D8: =IF($B8>Inputs!$B$11,"",I7) -> 1458127.5 | E8: =IF($B8>Inputs!$B$11,"",IF($B8>=Inputs!$B$10,0,Retirement!$B$49*12*(1+Inputs!$B$53)^(A8-1))) -> 135255.22 | F8: =IF($B8>Inputs!$B$11,"",IF($B8<Inputs!$B$10,0,Retirement!$B$23*(1+Inputs!$B$45)^($B8-Inputs!$B$10))) -> 0 | G8: =IF($B8>Inputs!$B$11,"",IF($B8<Inputs!$B$10,Inputs!$B$51,Inputs!$B$52)) -> 0.1075 | H8: =IF($B8>Inputs!$B$11,"",(D8-F8)*G8) -> 156748.71 | I8: =IF($B8>Inputs!$B$11,"",D8-F8+H8+E8) -> 1750131.4 | J8: =IF($B8>Inputs!$B$11,"",I8/(1+Inputs!$B$45)^A8) -> 1386268
A9: 5 | B9: =IF(Inputs!$B$9+4>Inputs!$B$11,"",Inputs!$B$9+4) -> 28 | C9: =IF($B9>Inputs!$B$11,"",IF($B9<Inputs!$B$10,"Accumulation","Retirement")) -> Accumulation | D9: =IF($B9>Inputs!$B$11,"",I8) -> 1750131.4 | E9: =IF($B9>Inputs!$B$11,"",IF($B9>=Inputs!$B$10,0,Retirement!$B$49*12*(1+Inputs!$B$53)^(A9-1))) -> 148780.74 | F9: =IF($B9>Inputs!$B$11,"",IF($B9<Inputs!$B$10,0,Retirement!$B$23*(1+Inputs!$B$45)^($B9-Inputs!$B$10))) -> 0 | G9: =IF($B9>Inputs!$B$11,"",IF($B9<Inputs!$B$10,Inputs!$B$51,Inputs!$B$52)) -> 0.1075 | H9: =IF($B9>Inputs!$B$11,"",(D9-F9)*G9) -> 188139.13 | I9: =IF($B9>Inputs!$B$11,"",D9-F9+H9+E9) -> 2087051.3 | J9: =IF($B9>Inputs!$B$11,"",I9/(1+Inputs!$B$45)^A9) -> 1559566.1
A10: 6 | B10: =IF(Inputs!$B$9+5>Inputs!$B$11,"",Inputs!$B$9+5) -> 29 | C10: =IF($B10>Inputs!$B$11,"",IF($B10<Inputs!$B$10,"Accumulation","Retirement")) -> Accumulation | D10: =IF($B10>Inputs!$B$11,"",I9) -> 2087051.3 | E10: =IF($B10>Inputs!$B$11,"",IF($B10>=Inputs!$B$10,0,Retirement!$B$49*12*(1+Inputs!$B$53)^(A10-1))) -> 163658.81 | F10: =IF($B10>Inputs!$B$11,"",IF($B10<Inputs!$B$10,0,Retirement!$B$23*(1+Inputs!$B$45)^($B10-Inputs!$B$10))) -> 0 | G10: =IF($B10>Inputs!$B$11,"",IF($B10<Inputs!$B$10,Inputs!$B$51,Inputs!$B$52)) -> 0.1075 | H10: =IF($B10>Inputs!$B$11,"",(D10-F10)*G10) -> 224358.01 | I10: =IF($B10>Inputs!$B$11,"",D10-F10+H10+E10) -> 2475068.1 | J10: =IF($B10>Inputs!$B$11,"",I10/(1+Inputs!$B$45)^A10) -> 1744825.3
A11: 7 | B11: =IF(Inputs!$B$9+6>Inputs!$B$11,"",Inputs!$B$9+6) -> 30 | C11: =IF($B11>Inputs!$B$11,"",IF($B11<Inputs!$B$10,"Accumulation","Retirement")) -> Accumulation | D11: =IF($B11>Inputs!$B$11,"",I10) -> 2475068.1 | E11: =IF($B11>Inputs!$B$11,"",IF($B11>=Inputs!$B$10,0,Retirement!$B$49*12*(1+Inputs!$B$53)^(A11-1))) -> 180024.69 | F11: =IF($B11>Inputs!$B$11,"",IF($B11<Inputs!$B$10,0,Retirement!$B$23*(1+Inputs!$B$45)^($B11-Inputs!$B$10))) -> 0 | G11: =IF($B11>Inputs!$B$11,"",IF($B11<Inputs!$B$10,Inputs!$B$51,Inputs!$B$52)) -> 0.1075 | H11: =IF($B11>Inputs!$B$11,"",(D11-F11)*G11) -> 266069.82 | I11: =IF($B11>Inputs!$B$11,"",D11-F11+H11+E11) -> 2921162.6 | J11: =IF($B11>Inputs!$B$11,"",I11/(1+Inputs!$B$45)^A11) -> 1942740
A12: 8 | B12: =IF(Inputs!$B$9+7>Inputs!$B$11,"",Inputs!$B$9+7) -> 31 | C12: =IF($B12>Inputs!$B$11,"",IF($B12<Inputs!$B$10,"Accumulation","Retirement")) -> Accumulation | D12: =IF($B12>Inputs!$B$11,"",I11) -> 2921162.6 | E12: =IF($B12>Inputs!$B$11,"",IF($B12>=Inputs!$B$10,0,Retirement!$B$49*12*(1+Inputs!$B$53)^(A12-1))) -> 198027.16 | F12: =IF($B12>Inputs!$B$11,"",IF($B12<Inputs!$B$10,0,Retirement!$B$23*(1+Inputs!$B$45)^($B12-Inputs!$B$10))) -> 0 | G12: =IF($B12>Inputs!$B$11,"",IF($B12<Inputs!$B$10,Inputs!$B$51,Inputs!$B$52)) -> 0.1075 | H12: =IF($B12>Inputs!$B$11,"",(D12-F12)*G12) -> 314024.98 | I12: =IF($B12>Inputs!$B$11,"",D12-F12+H12+E12) -> 3433214.8 | J12: =IF($B12>Inputs!$B$11,"",I12/(1+Inputs!$B$45)^A12) -> 2154041.4
A13: 9 | B13: =IF(Inputs!$B$9+8>Inputs!$B$11,"",Inputs!$B$9+8) -> 32 | C13: =IF($B13>Inputs!$B$11,"",IF($B13<Inputs!$B$10,"Accumulation","Retirement")) -> Accumulation | D13: =IF($B13>Inputs!$B$11,"",I12) -> 3433214.8 | E13: =IF($B13>Inputs!$B$11,"",IF($B13>=Inputs!$B$10,0,Retirement!$B$49*12*(1+Inputs!$B$53)^(A13-1))) -> 217829.88 | F13: =IF($B13>Inputs!$B$11,"",IF($B13<Inputs!$B$10,0,Retirement!$B$23*(1+Inputs!$B$45)^($B13-Inputs!$B$10))) -> 0 | G13: =IF($B13>Inputs!$B$11,"",IF($B13<Inputs!$B$10,Inputs!$B$51,Inputs!$B$52)) -> 0.1075 | H13: =IF($B13>Inputs!$B$11,"",(D13-F13)*G13) -> 369070.59 | I13: =IF($B13>Inputs!$B$11,"",D13-F13+H13+E13) -> 4020115.2 | J13: =IF($B13>Inputs!$B$11,"",I13/(1+Inputs!$B$45)^A13) -> 2379500
A14: 10 | B14: =IF(Inputs!$B$9+9>Inputs!$B$11,"",Inputs!$B$9+9) -> 33 | C14: =IF($B14>Inputs!$B$11,"",IF($B14<Inputs!$B$10,"Accumulation","Retirement")) -> Accumulation | D14: =IF($B14>Inputs!$B$11,"",I13) -> 4020115.2 | E14: =IF($B14>Inputs!$B$11,"",IF($B14>=Inputs!$B$10,0,Retirement!$B$49*12*(1+Inputs!$B$53)^(A14-1))) -> 239612.87 | F14: =IF($B14>Inputs!$B$11,"",IF($B14<Inputs!$B$10,0,Retirement!$B$23*(1+Inputs!$B$45)^($B14-Inputs!$B$10))) -> 0 | G14: =IF($B14>Inputs!$B$11,"",IF($B14<Inputs!$B$10,Inputs!$B$51,Inputs!$B$52)) -> 0.1075 | H14: =IF($B14>Inputs!$B$11,"",(D14-F14)*G14) -> 432162.39 | I14: =IF($B14>Inputs!$B$11,"",D14-F14+H14+E14) -> 4691890.5 | J14: =IF($B14>Inputs!$B$11,"",I14/(1+Inputs!$B$45)^A14) -> 2619927.1
A15: 11 | B15: =IF(Inputs!$B$9+10>Inputs!$B$11,"",Inputs!$B$9+10) -> 34 | C15: =IF($B15>Inputs!$B$11,"",IF($B15<Inputs!$B$10,"Accumulation","Retirement")) -> Accumulation | D15: =IF($B15>Inputs!$B$11,"",I14) -> 4691890.5 | E15: =IF($B15>Inputs!$B$11,"",IF($B15>=Inputs!$B$10,0,Retirement!$B$49*12*(1+Inputs!$B$53)^(A15-1))) -> 263574.15 | F15: =IF($B15>Inputs!$B$11,"",IF($B15<Inputs!$B$10,0,Retirement!$B$23*(1+Inputs!$B$45)^($B15-Inputs!$B$10))) -> 0 | G15: =IF($B15>Inputs!$B$11,"",IF($B15<Inputs!$B$10,Inputs!$B$51,Inputs!$B$52)) -> 0.1075 | H15: =IF($B15>Inputs!$B$11,"",(D15-F15)*G15) -> 504378.23 | I15: =IF($B15>Inputs!$B$11,"",D15-F15+H15+E15) -> 5459842.9 | J15: =IF($B15>Inputs!$B$11,"",I15/(1+Inputs!$B$45)^A15) -> 2876177.1
A16: 12 | B16: =IF(Inputs!$B$9+11>Inputs!$B$11,"",Inputs!$B$9+11) -> 35 | C16: =IF($B16>Inputs!$B$11,"",IF($B16<Inputs!$B$10,"Accumulation","Retirement")) -> Accumulation | D16: =IF($B16>Inputs!$B$11,"",I15) -> 5459842.9 | E16: =IF($B16>Inputs!$B$11,"",IF($B16>=Inputs!$B$10,0,Retirement!$B$49*12*(1+Inputs!$B$53)^(A16-1))) -> 289931.57 | F16: =IF($B16>Inputs!$B$11,"",IF($B16<Inputs!$B$10,0,Retirement!$B$23*(1+Inputs!$B$45)^($B16-Inputs!$B$10))) -> 0 | G16: =IF($B16>Inputs!$B$11,"",IF($B16<Inputs!$B$10,Inputs!$B$51,Inputs!$B$52)) -> 0.1075 | H16: =IF($B16>Inputs!$B$11,"",(D16-F16)*G16) -> 586933.11 | I16: =IF($B16>Inputs!$B$11,"",D16-F16+H16+E16) -> 6336707.5 | J16: =IF($B16>Inputs!$B$11,"",I16/(1+Inputs!$B$45)^A16) -> 3149149.5
A17: 13 | B17: =IF(Inputs!$B$9+12>Inputs!$B$11,"",Inputs!$B$9+12) -> 36 | C17: =IF($B17>Inputs!$B$11,"",IF($B17<Inputs!$B$10,"Accumulation","Retirement")) -> Accumulation | D17: =IF($B17>Inputs!$B$11,"",I16) -> 6336707.5 | E17: =IF($B17>Inputs!$B$11,"",IF($B17>=Inputs!$B$10,0,Retirement!$B$49*12*(1+Inputs!$B$53)^(A17-1))) -> 318924.72 | F17: =IF($B17>Inputs!$B$11,"",IF($B17<Inputs!$B$10,0,Retirement!$B$23*(1+Inputs!$B$45)^($B17-Inputs!$B$10))) -> 0 | G17: =IF($B17>Inputs!$B$11,"",IF($B17<Inputs!$B$10,Inputs!$B$51,Inputs!$B$52)) -> 0.1075 | H17: =IF($B17>Inputs!$B$11,"",(D17-F17)*G17) -> 681196.06 | I17: =IF($B17>Inputs!$B$11,"",D17-F17+H17+E17) -> 7336828.3 | J17: =IF($B17>Inputs!$B$11,"",I17/(1+Inputs!$B$45)^A17) -> 3439791.4
A18: 14 | B18: =IF(Inputs!$B$9+13>Inputs!$B$11,"",Inputs!$B$9+13) -> 37 | C18: =IF($B18>Inputs!$B$11,"",IF($B18<Inputs!$B$10,"Accumulation","Retirement")) -> Accumulation | D18: =IF($B18>Inputs!$B$11,"",I17) -> 7336828.3 | E18: =IF($B18>Inputs!$B$11,"",IF($B18>=Inputs!$B$10,0,Retirement!$B$49*12*(1+Inputs!$B$53)^(A18-1))) -> 350817.2 | F18: =IF($B18>Inputs!$B$11,"",IF($B18<Inputs!$B$10,0,Retirement!$B$23*(1+Inputs!$B$45)^($B18-Inputs!$B$10))) -> 0 | G18: =IF($B18>Inputs!$B$11,"",IF($B18<Inputs!$B$10,Inputs!$B$51,Inputs!$B$52)) -> 0.1075 | H18: =IF($B18>Inputs!$B$11,"",(D18-F18)*G18) -> 788709.04 | I18: =IF($B18>Inputs!$B$11,"",D18-F18+H18+E18) -> 8476354.6 | J18: =IF($B18>Inputs!$B$11,"",I18/(1+Inputs!$B$45)^A18) -> 3749099.8
A19: 15 | B19: =IF(Inputs!$B$9+14>Inputs!$B$11,"",Inputs!$B$9+14) -> 38 | C19: =IF($B19>Inputs!$B$11,"",IF($B19<Inputs!$B$10,"Accumulation","Retirement")) -> Accumulation | D19: =IF($B19>Inputs!$B$11,"",I18) -> 8476354.6 | E19: =IF($B19>Inputs!$B$11,"",IF($B19>=Inputs!$B$10,0,Retirement!$B$49*12*(1+Inputs!$B$53)^(A19-1))) -> 385898.92 | F19: =IF($B19>Inputs!$B$11,"",IF($B19<Inputs!$B$10,0,Retirement!$B$23*(1+Inputs!$B$45)^($B19-Inputs!$B$10))) -> 0 | G19: =IF($B19>Inputs!$B$11,"",IF($B19<Inputs!$B$10,Inputs!$B$51,Inputs!$B$52)) -> 0.1075 | H19: =IF($B19>Inputs!$B$11,"",(D19-F19)*G19) -> 911208.11 | I19: =IF($B19>Inputs!$B$11,"",D19-F19+H19+E19) -> 9773461.6 | J19: =IF($B19>Inputs!$B$11,"",I19/(1+Inputs!$B$45)^A19) -> 4078124
A20: 16 | B20: =IF(Inputs!$B$9+15>Inputs!$B$11,"",Inputs!$B$9+15) -> 39 | C20: =IF($B20>Inputs!$B$11,"",IF($B20<Inputs!$B$10,"Accumulation","Retirement")) -> Accumulation | D20: =IF($B20>Inputs!$B$11,"",I19) -> 9773461.6 | E20: =IF($B20>Inputs!$B$11,"",IF($B20>=Inputs!$B$10,0,Retirement!$B$49*12*(1+Inputs!$B$53)^(A20-1))) -> 424488.81 | F20: =IF($B20>Inputs!$B$11,"",IF($B20<Inputs!$B$10,0,Retirement!$B$23*(1+Inputs!$B$45)^($B20-Inputs!$B$10))) -> 0 | G20: =IF($B20>Inputs!$B$11,"",IF($B20<Inputs!$B$10,Inputs!$B$51,Inputs!$B$52)) -> 0.1075 | H20: =IF($B20>Inputs!$B$11,"",(D20-F20)*G20) -> 1050647.1 | I20: =IF($B20>Inputs!$B$11,"",D20-F20+H20+E20) -> 11248598 | J20: =IF($B20>Inputs!$B$11,"",I20/(1+Inputs!$B$45)^A20) -> 4427968.6
A21: 17 | B21: =IF(Inputs!$B$9+16>Inputs!$B$11,"",Inputs!$B$9+16) -> 40 | C21: =IF($B21>Inputs!$B$11,"",IF($B21<Inputs!$B$10,"Accumulation","Retirement")) -> Accumulation | D21: =IF($B21>Inputs!$B$11,"",I20) -> 11248598 | E21: =IF($B21>Inputs!$B$11,"",IF($B21>=Inputs!$B$10,0,Retirement!$B$49*12*(1+Inputs!$B$53)^(A21-1))) -> 466937.69 | F21: =IF($B21>Inputs!$B$11,"",IF($B21<Inputs!$B$10,0,Retirement!$B$23*(1+Inputs!$B$45)^($B21-Inputs!$B$10))) -> 0 | G21: =IF($B21>Inputs!$B$11,"",IF($B21<Inputs!$B$10,Inputs!$B$51,Inputs!$B$52)) -> 0.1075 | H21: =IF($B21>Inputs!$B$11,"",(D21-F21)*G21) -> 1209224.2 | I21: =IF($B21>Inputs!$B$11,"",D21-F21+H21+E21) -> 12924759 | J21: =IF($B21>Inputs!$B$11,"",I21/(1+Inputs!$B$45)^A21) -> 4799795.8
A22: 18 | B22: =IF(Inputs!$B$9+17>Inputs!$B$11,"",Inputs!$B$9+17) -> 41 | C22: =IF($B22>Inputs!$B$11,"",IF($B22<Inputs!$B$10,"Accumulation","Retirement")) -> Accumulation | D22: =IF($B22>Inputs!$B$11,"",I21) -> 12924759 | E22: =IF($B22>Inputs!$B$11,"",IF($B22>=Inputs!$B$10,0,Retirement!$B$49*12*(1+Inputs!$B$53)^(A22-1))) -> 513631.46 | F22: =IF($B22>Inputs!$B$11,"",IF($B22<Inputs!$B$10,0,Retirement!$B$23*(1+Inputs!$B$45)^($B22-Inputs!$B$10))) -> 0 | G22: =IF($B22>Inputs!$B$11,"",IF($B22<Inputs!$B$10,Inputs!$B$51,Inputs!$B$52)) -> 0.1075 | H22: =IF($B22>Inputs!$B$11,"",(D22-F22)*G22) -> 1389411.6 | I22: =IF($B22>Inputs!$B$11,"",D22-F22+H22+E22) -> 14827803 | J22: =IF($B22>Inputs!$B$11,"",I22/(1+Inputs!$B$45)^A22) -> 5194828.6
A23: 19 | B23: =IF(Inputs!$B$9+18>Inputs!$B$11,"",Inputs!$B$9+18) -> 42 | C23: =IF($B23>Inputs!$B$11,"",IF($B23<Inputs!$B$10,"Accumulation","Retirement")) -> Accumulation | D23: =IF($B23>Inputs!$B$11,"",I22) -> 14827803 | E23: =IF($B23>Inputs!$B$11,"",IF($B23>=Inputs!$B$10,0,Retirement!$B$49*12*(1+Inputs!$B$53)^(A23-1))) -> 564994.6 | F23: =IF($B23>Inputs!$B$11,"",IF($B23<Inputs!$B$10,0,Retirement!$B$23*(1+Inputs!$B$45)^($B23-Inputs!$B$10))) -> 0 | G23: =IF($B23>Inputs!$B$11,"",IF($B23<Inputs!$B$10,Inputs!$B$51,Inputs!$B$52)) -> 0.1075 | H23: =IF($B23>Inputs!$B$11,"",(D23-F23)*G23) -> 1593988.8 | I23: =IF($B23>Inputs!$B$11,"",D23-F23+H23+E23) -> 16986786 | J23: =IF($B23>Inputs!$B$11,"",I23/(1+Inputs!$B$45)^A23) -> 5614353.8
A24: 20 | B24: =IF(Inputs!$B$9+19>Inputs!$B$11,"",Inputs!$B$9+19) -> 43 | C24: =IF($B24>Inputs!$B$11,"",IF($B24<Inputs!$B$10,"Accumulation","Retirement")) -> Accumulation | D24: =IF($B24>Inputs!$B$11,"",I23) -> 16986786 | E24: =IF($B24>Inputs!$B$11,"",IF($B24>=Inputs!$B$10,0,Retirement!$B$49*12*(1+Inputs!$B$53)^(A24-1))) -> 621494.06 | F24: =IF($B24>Inputs!$B$11,"",IF($B24<Inputs!$B$10,0,Retirement!$B$23*(1+Inputs!$B$45)^($B24-Inputs!$B$10))) -> 0 | G24: =IF($B24>Inputs!$B$11,"",IF($B24<Inputs!$B$10,Inputs!$B$51,Inputs!$B$52)) -> 0.1075 | H24: =IF($B24>Inputs!$B$11,"",(D24-F24)*G24) -> 1826079.5 | I24: =IF($B24>Inputs!$B$11,"",D24-F24+H24+E24) -> 19434359 | J24: =IF($B24>Inputs!$B$11,"",I24/(1+Inputs!$B$45)^A24) -> 6059725.1
A25: 21 | B25: =IF(Inputs!$B$9+20>Inputs!$B$11,"",Inputs!$B$9+20) -> 44 | C25: =IF($B25>Inputs!$B$11,"",IF($B25<Inputs!$B$10,"Accumulation","Retirement")) -> Accumulation | D25: =IF($B25>Inputs!$B$11,"",I24) -> 19434359 | E25: =IF($B25>Inputs!$B$11,"",IF($B25>=Inputs!$B$10,0,Retirement!$B$49*12*(1+Inputs!$B$53)^(A25-1))) -> 683643.47 | F25: =IF($B25>Inputs!$B$11,"",IF($B25<Inputs!$B$10,0,Retirement!$B$23*(1+Inputs!$B$45)^($B25-Inputs!$B$10))) -> 0 | G25: =IF($B25>Inputs!$B$11,"",IF($B25<Inputs!$B$10,Inputs!$B$51,Inputs!$B$52)) -> 0.1075 | H25: =IF($B25>Inputs!$B$11,"",(D25-F25)*G25) -> 2089193.6 | I25: =IF($B25>Inputs!$B$11,"",D25-F25+H25+E25) -> 22207197 | J25: =IF($B25>Inputs!$B$11,"",I25/(1+Inputs!$B$45)^A25) -> 6532366.9
A26: 22 | B26: =IF(Inputs!$B$9+21>Inputs!$B$11,"",Inputs!$B$9+21) -> 45 | C26: =IF($B26>Inputs!$B$11,"",IF($B26<Inputs!$B$10,"Accumulation","Retirement")) -> Accumulation | D26: =IF($B26>Inputs!$B$11,"",I25) -> 22207197 | E26: =IF($B26>Inputs!$B$11,"",IF($B26>=Inputs!$B$10,0,Retirement!$B$49*12*(1+Inputs!$B$53)^(A26-1))) -> 752007.82 | F26: =IF($B26>Inputs!$B$11,"",IF($B26<Inputs!$B$10,0,Retirement!$B$23*(1+Inputs!$B$45)^($B26-Inputs!$B$10))) -> 0 | G26: =IF($B26>Inputs!$B$11,"",IF($B26<Inputs!$B$10,Inputs!$B$51,Inputs!$B$52)) -> 0.1075 | H26: =IF($B26>Inputs!$B$11,"",(D26-F26)*G26) -> 2387273.6 | I26: =IF($B26>Inputs!$B$11,"",D26-F26+H26+E26) -> 25346478 | J26: =IF($B26>Inputs!$B$11,"",I26/(1+Inputs!$B$45)^A26) -> 7033776.8
A27: 23 | B27: =IF(Inputs!$B$9+22>Inputs!$B$11,"",Inputs!$B$9+22) -> 46 | C27: =IF($B27>Inputs!$B$11,"",IF($B27<Inputs!$B$10,"Accumulation","Retirement")) -> Accumulation | D27: =IF($B27>Inputs!$B$11,"",I26) -> 25346478 | E27: =IF($B27>Inputs!$B$11,"",IF($B27>=Inputs!$B$10,0,Retirement!$B$49*12*(1+Inputs!$B$53)^(A27-1))) -> 827208.6 | F27: =IF($B27>Inputs!$B$11,"",IF($B27<Inputs!$B$10,0,Retirement!$B$23*(1+Inputs!$B$45)^($B27-Inputs!$B$10))) -> 0 | G27: =IF($B27>Inputs!$B$11,"",IF($B27<Inputs!$B$10,Inputs!$B$51,Inputs!$B$52)) -> 0.1075 | H27: =IF($B27>Inputs!$B$11,"",(D27-F27)*G27) -> 2724746.4 | I27: =IF($B27>Inputs!$B$11,"",D27-F27+H27+E27) -> 28898433 | J27: =IF($B27>Inputs!$B$11,"",I27/(1+Inputs!$B$45)^A27) -> 7565530.6
A28: 24 | B28: =IF(Inputs!$B$9+23>Inputs!$B$11,"",Inputs!$B$9+23) -> 47 | C28: =IF($B28>Inputs!$B$11,"",IF($B28<Inputs!$B$10,"Accumulation","Retirement")) -> Accumulation | D28: =IF($B28>Inputs!$B$11,"",I27) -> 28898433 | E28: =IF($B28>Inputs!$B$11,"",IF($B28>=Inputs!$B$10,0,Retirement!$B$49*12*(1+Inputs!$B$53)^(A28-1))) -> 909929.46 | F28: =IF($B28>Inputs!$B$11,"",IF($B28<Inputs!$B$10,0,Retirement!$B$23*(1+Inputs!$B$45)^($B28-Inputs!$B$10))) -> 0 | G28: =IF($B28>Inputs!$B$11,"",IF($B28<Inputs!$B$10,Inputs!$B$51,Inputs!$B$52)) -> 0.1075 | H28: =IF($B28>Inputs!$B$11,"",(D28-F28)*G28) -> 3106581.5 | I28: =IF($B28>Inputs!$B$11,"",D28-F28+H28+E28) -> 32914944 | J28: =IF($B28>Inputs!$B$11,"",I28/(1+Inputs!$B$45)^A28) -> 8129285.1
A29: 25 | B29: =IF(Inputs!$B$9+24>Inputs!$B$11,"",Inputs!$B$9+24) -> 48 | C29: =IF($B29>Inputs!$B$11,"",IF($B29<Inputs!$B$10,"Accumulation","Retirement")) -> Accumulation | D29: =IF($B29>Inputs!$B$11,"",I28) -> 32914944 | E29: =IF($B29>Inputs!$B$11,"",IF($B29>=Inputs!$B$10,0,Retirement!$B$49*12*(1+Inputs!$B$53)^(A29-1))) -> 1000922.4 | F29: =IF($B29>Inputs!$B$11,"",IF($B29<Inputs!$B$10,0,Retirement!$B$23*(1+Inputs!$B$45)^($B29-Inputs!$B$10))) -> 0 | G29: =IF($B29>Inputs!$B$11,"",IF($B29<Inputs!$B$10,Inputs!$B$51,Inputs!$B$52)) -> 0.1075 | H29: =IF($B29>Inputs!$B$11,"",(D29-F29)*G29) -> 3538356.5 | I29: =IF($B29>Inputs!$B$11,"",D29-F29+H29+E29) -> 37454223 | J29: =IF($B29>Inputs!$B$11,"",I29/(1+Inputs!$B$45)^A29) -> 8726782.6
A30: 26 | B30: =IF(Inputs!$B$9+25>Inputs!$B$11,"",Inputs!$B$9+25) -> 49 | C30: =IF($B30>Inputs!$B$11,"",IF($B30<Inputs!$B$10,"Accumulation","Retirement")) -> Accumulation | D30: =IF($B30>Inputs!$B$11,"",I29) -> 37454223 | E30: =IF($B30>Inputs!$B$11,"",IF($B30>=Inputs!$B$10,0,Retirement!$B$49*12*(1+Inputs!$B$53)^(A30-1))) -> 1101014.6 | F30: =IF($B30>Inputs!$B$11,"",IF($B30<Inputs!$B$10,0,Retirement!$B$23*(1+Inputs!$B$45)^($B30-Inputs!$B$10))) -> 0 | G30: =IF($B30>Inputs!$B$11,"",IF($B30<Inputs!$B$10,Inputs!$B$51,Inputs!$B$52)) -> 0.1075 | H30: =IF($B30>Inputs!$B$11,"",(D30-F30)*G30) -> 4026329 | I30: =IF($B30>Inputs!$B$11,"",D30-F30+H30+E30) -> 42581567 | J30: =IF($B30>Inputs!$B$11,"",I30/(1+Inputs!$B$45)^A30) -> 9359855.4
A31: 27 | B31: =IF(Inputs!$B$9+26>Inputs!$B$11,"",Inputs!$B$9+26) -> 50 | C31: =IF($B31>Inputs!$B$11,"",IF($B31<Inputs!$B$10,"Accumulation","Retirement")) -> Accumulation | D31: =IF($B31>Inputs!$B$11,"",I30) -> 42581567 | E31: =IF($B31>Inputs!$B$11,"",IF($B31>=Inputs!$B$10,0,Retirement!$B$49*12*(1+Inputs!$B$53)^(A31-1))) -> 1211116.1 | F31: =IF($B31>Inputs!$B$11,"",IF($B31<Inputs!$B$10,0,Retirement!$B$23*(1+Inputs!$B$45)^($B31-Inputs!$B$10))) -> 0 | G31: =IF($B31>Inputs!$B$11,"",IF($B31<Inputs!$B$10,Inputs!$B$51,Inputs!$B$52)) -> 0.1075 | H31: =IF($B31>Inputs!$B$11,"",(D31-F31)*G31) -> 4577518.4 | I31: =IF($B31>Inputs!$B$11,"",D31-F31+H31+E31) -> 48370201 | J31: =IF($B31>Inputs!$B$11,"",I31/(1+Inputs!$B$45)^A31) -> 10030430
A32: 28 | B32: =IF(Inputs!$B$9+27>Inputs!$B$11,"",Inputs!$B$9+27) -> 51 | C32: =IF($B32>Inputs!$B$11,"",IF($B32<Inputs!$B$10,"Accumulation","Retirement")) -> Accumulation | D32: =IF($B32>Inputs!$B$11,"",I31) -> 48370201 | E32: =IF($B32>Inputs!$B$11,"",IF($B32>=Inputs!$B$10,0,Retirement!$B$49*12*(1+Inputs!$B$53)^(A32-1))) -> 1332227.7 | F32: =IF($B32>Inputs!$B$11,"",IF($B32<Inputs!$B$10,0,Retirement!$B$23*(1+Inputs!$B$45)^($B32-Inputs!$B$10))) -> 0 | G32: =IF($B32>Inputs!$B$11,"",IF($B32<Inputs!$B$10,Inputs!$B$51,Inputs!$B$52)) -> 0.1075 | H32: =IF($B32>Inputs!$B$11,"",(D32-F32)*G32) -> 5199796.6 | I32: =IF($B32>Inputs!$B$11,"",D32-F32+H32+E32) -> 54902225 | J32: =IF($B32>Inputs!$B$11,"",I32/(1+Inputs!$B$45)^A32) -> 10740530
A33: 29 | B33: =IF(Inputs!$B$9+28>Inputs!$B$11,"",Inputs!$B$9+28) -> 52 | C33: =IF($B33>Inputs!$B$11,"",IF($B33<Inputs!$B$10,"Accumulation","Retirement")) -> Accumulation | D33: =IF($B33>Inputs!$B$11,"",I32) -> 54902225 | E33: =IF($B33>Inputs!$B$11,"",IF($B33>=Inputs!$B$10,0,Retirement!$B$49*12*(1+Inputs!$B$53)^(A33-1))) -> 1465450.5 | F33: =IF($B33>Inputs!$B$11,"",IF($B33<Inputs!$B$10,0,Retirement!$B$23*(1+Inputs!$B$45)^($B33-Inputs!$B$10))) -> 0 | G33: =IF($B33>Inputs!$B$11,"",IF($B33<Inputs!$B$10,Inputs!$B$51,Inputs!$B$52)) -> 0.1075 | H33: =IF($B33>Inputs!$B$11,"",(D33-F33)*G33) -> 5901989.2 | I33: =IF($B33>Inputs!$B$11,"",D33-F33+H33+E33) -> 62269665 | J33: =IF($B33>Inputs!$B$11,"",I33/(1+Inputs!$B$45)^A33) -> 11492286
A34: 30 | B34: =IF(Inputs!$B$9+29>Inputs!$B$11,"",Inputs!$B$9+29) -> 53 | C34: =IF($B34>Inputs!$B$11,"",IF($B34<Inputs!$B$10,"Accumulation","Retirement")) -> Accumulation | D34: =IF($B34>Inputs!$B$11,"",I33) -> 62269665 | E34: =IF($B34>Inputs!$B$11,"",IF($B34>=Inputs!$B$10,0,Retirement!$B$49*12*(1+Inputs!$B$53)^(A34-1))) -> 1611995.5 | F34: =IF($B34>Inputs!$B$11,"",IF($B34<Inputs!$B$10,0,Retirement!$B$23*(1+Inputs!$B$45)^($B34-Inputs!$B$10))) -> 0 | G34: =IF($B34>Inputs!$B$11,"",IF($B34<Inputs!$B$10,Inputs!$B$51,Inputs!$B$52)) -> 0.1075 | H34: =IF($B34>Inputs!$B$11,"",(D34-F34)*G34) -> 6693989 | I34: =IF($B34>Inputs!$B$11,"",D34-F34+H34+E34) -> 70575650 | J34: =IF($B34>Inputs!$B$11,"",I34/(1+Inputs!$B$45)^A34) -> 12287936
A35: 31 | B35: =IF(Inputs!$B$9+30>Inputs!$B$11,"",Inputs!$B$9+30) -> 54 | C35: =IF($B35>Inputs!$B$11,"",IF($B35<Inputs!$B$10,"Accumulation","Retirement")) -> Accumulation | D35: =IF($B35>Inputs!$B$11,"",I34) -> 70575650 | E35: =IF($B35>Inputs!$B$11,"",IF($B35>=Inputs!$B$10,0,Retirement!$B$49*12*(1+Inputs!$B$53)^(A35-1))) -> 1773195.1 | F35: =IF($B35>Inputs!$B$11,"",IF($B35<Inputs!$B$10,0,Retirement!$B$23*(1+Inputs!$B$45)^($B35-Inputs!$B$10))) -> 0 | G35: =IF($B35>Inputs!$B$11,"",IF($B35<Inputs!$B$10,Inputs!$B$51,Inputs!$B$52)) -> 0.1075 | H35: =IF($B35>Inputs!$B$11,"",(D35-F35)*G35) -> 7586882.3 | I35: =IF($B35>Inputs!$B$11,"",D35-F35+H35+E35) -> 79935727 | J35: =IF($B35>Inputs!$B$11,"",I35/(1+Inputs!$B$45)^A35) -> 13129830
A36: 32 | B36: =IF(Inputs!$B$9+31>Inputs!$B$11,"",Inputs!$B$9+31) -> 55 | C36: =IF($B36>Inputs!$B$11,"",IF($B36<Inputs!$B$10,"Accumulation","Retirement")) -> Accumulation | D36: =IF($B36>Inputs!$B$11,"",I35) -> 79935727 | E36: =IF($B36>Inputs!$B$11,"",IF($B36>=Inputs!$B$10,0,Retirement!$B$49*12*(1+Inputs!$B$53)^(A36-1))) -> 1950514.6 | F36: =IF($B36>Inputs!$B$11,"",IF($B36<Inputs!$B$10,0,Retirement!$B$23*(1+Inputs!$B$45)^($B36-Inputs!$B$10))) -> 0 | G36: =IF($B36>Inputs!$B$11,"",IF($B36<Inputs!$B$10,Inputs!$B$51,Inputs!$B$52)) -> 0.1075 | H36: =IF($B36>Inputs!$B$11,"",(D36-F36)*G36) -> 8593090.7 | I36: =IF($B36>Inputs!$B$11,"",D36-F36+H36+E36) -> 90479332 | J36: =IF($B36>Inputs!$B$11,"",I36/(1+Inputs!$B$45)^A36) -> 14020442
A37: 33 | B37: =IF(Inputs!$B$9+32>Inputs!$B$11,"",Inputs!$B$9+32) -> 56 | C37: =IF($B37>Inputs!$B$11,"",IF($B37<Inputs!$B$10,"Accumulation","Retirement")) -> Accumulation | D37: =IF($B37>Inputs!$B$11,"",I36) -> 90479332 | E37: =IF($B37>Inputs!$B$11,"",IF($B37>=Inputs!$B$10,0,Retirement!$B$49*12*(1+Inputs!$B$53)^(A37-1))) -> 2145566.1 | F37: =IF($B37>Inputs!$B$11,"",IF($B37<Inputs!$B$10,0,Retirement!$B$23*(1+Inputs!$B$45)^($B37-Inputs!$B$10))) -> 0 | G37: =IF($B37>Inputs!$B$11,"",IF($B37<Inputs!$B$10,Inputs!$B$51,Inputs!$B$52)) -> 0.1075 | H37: =IF($B37>Inputs!$B$11,"",(D37-F37)*G37) -> 9726528.2 | I37: =IF($B37>Inputs!$B$11,"",D37-F37+H37+E37) -> 1.0235143e+08 | J37: =IF($B37>Inputs!$B$11,"",I37/(1+Inputs!$B$45)^A37) -> 14962369
A38: 34 | B38: =IF(Inputs!$B$9+33>Inputs!$B$11,"",Inputs!$B$9+33) -> 57 | C38: =IF($B38>Inputs!$B$11,"",IF($B38<Inputs!$B$10,"Accumulation","Retirement")) -> Accumulation | D38: =IF($B38>Inputs!$B$11,"",I37) -> 1.0235143e+08 | E38: =IF($B38>Inputs!$B$11,"",IF($B38>=Inputs!$B$10,0,Retirement!$B$49*12*(1+Inputs!$B$53)^(A38-1))) -> 2360122.7 | F38: =IF($B38>Inputs!$B$11,"",IF($B38<Inputs!$B$10,0,Retirement!$B$23*(1+Inputs!$B$45)^($B38-Inputs!$B$10))) -> 0 | G38: =IF($B38>Inputs!$B$11,"",IF($B38<Inputs!$B$10,Inputs!$B$51,Inputs!$B$52)) -> 0.1075 | H38: =IF($B38>Inputs!$B$11,"",(D38-F38)*G38) -> 11002778 | I38: =IF($B38>Inputs!$B$11,"",D38-F38+H38+E38) -> 1.1571433e+08 | J38: =IF($B38>Inputs!$B$11,"",I38/(1+Inputs!$B$45)^A38) -> 15958340
A39: 35 | B39: =IF(Inputs!$B$9+34>Inputs!$B$11,"",Inputs!$B$9+34) -> 58 | C39: =IF($B39>Inputs!$B$11,"",IF($B39<Inputs!$B$10,"Accumulation","Retirement")) -> Accumulation | D39: =IF($B39>Inputs!$B$11,"",I38) -> 1.1571433e+08 | E39: =IF($B39>Inputs!$B$11,"",IF($B39>=Inputs!$B$10,0,Retirement!$B$49*12*(1+Inputs!$B$53)^(A39-1))) -> 2596134.9 | F39: =IF($B39>Inputs!$B$11,"",IF($B39<Inputs!$B$10,0,Retirement!$B$23*(1+Inputs!$B$45)^($B39-Inputs!$B$10))) -> 0 | G39: =IF($B39>Inputs!$B$11,"",IF($B39<Inputs!$B$10,Inputs!$B$51,Inputs!$B$52)) -> 0.1075 | H39: =IF($B39>Inputs!$B$11,"",(D39-F39)*G39) -> 12439290 | I39: =IF($B39>Inputs!$B$11,"",D39-F39+H39+E39) -> 1.3074975e+08 | J39: =IF($B39>Inputs!$B$11,"",I39/(1+Inputs!$B$45)^A39) -> 17011225
A40: 36 | B40: =IF(Inputs!$B$9+35>Inputs!$B$11,"",Inputs!$B$9+35) -> 59 | C40: =IF($B40>Inputs!$B$11,"",IF($B40<Inputs!$B$10,"Accumulation","Retirement")) -> Accumulation | D40: =IF($B40>Inputs!$B$11,"",I39) -> 1.3074975e+08 | E40: =IF($B40>Inputs!$B$11,"",IF($B40>=Inputs!$B$10,0,Retirement!$B$49*12*(1+Inputs!$B$53)^(A40-1))) -> 2855748.4 | F40: =IF($B40>Inputs!$B$11,"",IF($B40<Inputs!$B$10,0,Retirement!$B$23*(1+Inputs!$B$45)^($B40-Inputs!$B$10))) -> 0 | G40: =IF($B40>Inputs!$B$11,"",IF($B40<Inputs!$B$10,Inputs!$B$51,Inputs!$B$52)) -> 0.1075 | H40: =IF($B40>Inputs!$B$11,"",(D40-F40)*G40) -> 14055598 | I40: =IF($B40>Inputs!$B$11,"",D40-F40+H40+E40) -> 1.476611e+08 | J40: =IF($B40>Inputs!$B$11,"",I40/(1+Inputs!$B$45)^A40) -> 18124037
A41: 37 | B41: =IF(Inputs!$B$9+36>Inputs!$B$11,"",Inputs!$B$9+36) -> 60 | C41: =IF($B41>Inputs!$B$11,"",IF($B41<Inputs!$B$10,"Accumulation","Retirement")) -> Retirement | D41: =IF($B41>Inputs!$B$11,"",I40) -> 1.476611e+08 | E41: =IF($B41>Inputs!$B$11,"",IF($B41>=Inputs!$B$10,0,Retirement!$B$49*12*(1+Inputs!$B$53)^(A41-1))) -> 0 | F41: =IF($B41>Inputs!$B$11,"",IF($B41<Inputs!$B$10,0,Retirement!$B$23*(1+Inputs!$B$45)^($B41-Inputs!$B$10))) -> 5499395.1 | G41: =IF($B41>Inputs!$B$11,"",IF($B41<Inputs!$B$10,Inputs!$B$51,Inputs!$B$52)) -> 0.075 | H41: =IF($B41>Inputs!$B$11,"",(D41-F41)*G41) -> 10662128 | I41: =IF($B41>Inputs!$B$11,"",D41-F41+H41+E41) -> 1.5282383e+08 | J41: =IF($B41>Inputs!$B$11,"",I41/(1+Inputs!$B$45)^A41) -> 17695958
...

Sheet Calculators
A1: 6. STANDALONE CALCULATORS - USE FOR ANY CLIENT, ANY SCENARIO
A3: These blocks are INDEPENDENT of the rest of the workbook. Type into the yellow cells and read the answer. Nothing here feeds the plan, so experiment freely.
A5: CALC 1 - SIP FUTURE VALUE (what will my monthly SIP become?)
A6: Parameter | B6: Value | C6: Unit | D6: Formula / Logic Used
A7: Monthly SIP Amount | B7: 25000 | C7: ₹ p.m. | D7: Your input.
A8: Expected Annual Return | B8: 0.12 | C8: % | D8: Your input.
A9: Investment Period | B9: 20 | C9: years | D9: Your input.
A10: Future Value | B10: =FV(B8/12,B9*12,-B7) -> 24731384 | C10: ₹ | D10: Formula: FV(Annual Return / 12, Years x 12, -Monthly SIP). Rate and period are both converted to MONTHS because the instalment is monthly. The SIP is negative because it is cash leaving your pocket.
A11: Total Amount Invested | B11: =B7*B9*12 -> 6000000 | C11: ₹ | D11: Formula: Monthly SIP x Years x 12
A12: Wealth Gained | B12: =B10-B11 -> 18731384 | C12: ₹ | D12: Formula: Future Value - Total Invested
A13: Gain Multiple | B13: =IFERROR(B10/B11,0) -> 4.1218974 | C13: x | D13: Formula: Future Value / Total Invested
A15: CALC 2 - STEP-UP SIP FUTURE VALUE (SIP increased every year)
A16: Parameter | B16: Value | C16: Unit | D16: Formula / Logic Used
A17: Year-1 Monthly SIP | B17: 20000 | C17: ₹ p.m. | D17: Your input.
A18: Annual Step-Up Rate | B18: 0.1 | C18: % | D18: How much you raise the SIP each year.
A19: Expected Annual Return | B19: 0.12 | C19: % | D19: Your input.
A20: Investment Period | B20: 20 | C20: years | D20: Your input.
A21: Future Value | B21: =IF(ABS(B19-B18)<0.0001,B17*12*B20*(1+B19)^(B20-1),B17*12*((1+B19)^B20-(1+B18)^B20)/(B19-B18)) -> 35025518 | C21: ₹ | D21: Formula: A x [ (1+r)^n - (1+g)^n ] / (r - g), where A = year-1 ANNUAL investment, r = return, g = step-up rate, n = years. Future value of a growing annuity. The IF handles the r = g case, where the formula would divide by zero.
A22: Total Amount Invested | B22: =IF(ABS(B18)<0.0001,B17*12*B20,B17*12*((1+B18)^B20-1)/B18) -> 13746000 | C22: ₹ | D22: Formula: A x [ (1+g)^n - 1 ] / g. Sum of a geometric series - the contributions themselves, before any return.
A23: Wealth Gained | B23: =B21-B22 -> 21279518 | C23: ₹ | D23: Formula: Future Value - Total Invested
A25: CALC 3 - LUMPSUM FUTURE VALUE
A26: Parameter | B26: Value | C26: Unit | D26: Formula / Logic Used
A27: Lumpsum Invested Today | B27: 1000000 | C27: ₹ | D27: Your input.
A28: Expected Annual Return | B28: 0.12 | C28: % | D28: Your input.
A29: Investment Period | B29: 20 | C29: years | D29: Your input.
A30: Future Value | B30: =FV(B28,B29,0,-B27) -> 9646293.1 | C30: ₹ | D30: Formula: FV(Return, Years, 0, -Lumpsum). Equivalent to Lumpsum x (1 + Return) ^ Years. The 0 is the payment argument: there are no recurring instalments.
A31: Wealth Gained | B31: =B30-B27 -> 8646293.1 | C31: ₹ | D31: Formula: Future Value - Amount Invested
A33: CALC 4 - SIP NEEDED FOR A TARGET (goal-based, reverse SIP)
A34: Parameter | B34: Value | C34: Unit | D34: Formula / Logic Used
A35: Target Amount (future value needed) | B35: 10000000 | C35: ₹ | D35: Your input.
A36: Expected Annual Return | B36: 0.12 | C36: % | D36: Your input.
A37: Time Available | B37: 15 | C37: years | D37: Your input.
A38: Monthly SIP Required | B38: =-PMT(B36/12,B37*12,0,B35) -> 20016.806 | C38: ₹ p.m. | D38: Formula: -PMT(Return / 12, Years x 12, 0, Target). PMT solves for the instalment that turns a present value of 0 into the target. The leading minus flips the sign from outflow to a readable positive.
